<?xml version="1.0"?>
<robot name="pioneer3dx" xmlns:xacro="http://ros.org/wiki/xacro">

  <!-- properties (constants) -->
  <property name="ns" value="p3dx" />
  <!-- properties (constants) -->
  <property name="M_PI" value="3.14159" />





        <!-- chassis -->
	<link name="base_link">
		<inertial>
			<mass value="3.5" />
			<!--<origin xyz="-0.025 0 -0.223"/> -->
			<origin xyz="-0.05 0 0" />
			<inertia ixx="1" ixy="0" ixz="0" iyy="1" iyz="0" izz="1" />
		</inertial>

		<visual name="base_visual">
			<origin xyz="-0.045 0 0.148" rpy="0 0 0" />
			<geometry name="pioneer_geom">
				<mesh filename="package://p3dx_description/meshes/chassis.stl" />
			</geometry>
			<material name="ChassisRed">
				<color rgba="0.851 0.0 0.0 1.0" />
			</material>
		</visual>

		<collision>
			<origin xyz="-0.045 0 0.145" rpy="0 0 0" />
			<geometry>
				<box size="0.35 0.25 0.14" />
			</geometry>
		</collision>
	</link>
	<gazebo reference="base_link">
		<material>Gazebo/Red</material>
	</gazebo>


 <!-- top_plate -->
	<link name="top_plate">
		<inertial>
			<mass value="0.01" />
			<origin xyz="0 0 0" />
			<inertia ixx="1" ixy="0" ixz="0" iyy="1" iyz="0" izz="1" />
		</inertial>

		<visual name="base_visual">
			<origin xyz="0 0 0" rpy="0 0 0" />
			<geometry name="top_geom">
				<mesh filename="package://p3dx_description/meshes/top.stl" />
			</geometry>

			<material name="TopBlack">
				<color rgba="0.038 0.038 0.038 1.0" />
			</material>
		</visual>

		<collision>
			<origin xyz="0.0 0 0" rpy="0 0 0" />
			<geometry name="pioneer_geom">
				<box size="0.45 0.38 0.01" />
			</geometry>
		</collision>
	</link>

	<joint name="base_top_joint" type="fixed">
		<origin xyz="-0.045 0 0.234" rpy="0 0 0" />
		<parent link="base_link" />
		<child link="top_plate" />
	</joint>
  <gazebo reference="top_plate">
    <material>Gazebo/Black</material>
  </gazebo>

 <!-- swivel -->
	<link name="swivel">
		<inertial>
			<mass value="0.1" />
			<origin xyz="0 0 0" />
			<inertia ixx="0.01" ixy="0" ixz="0" iyy="0.01" iyz="0" izz="0.01" />
		</inertial>

		<visual name="base_visual">
			<origin xyz="0 0 0" rpy="0 0 0" />
			<geometry name="pioneer_geom">
				<mesh filename="package://p3dx_description/meshes/swivel.stl" />
			</geometry>
			<material name="swivel">
				<color rgba="0.5 0.5 0.5 1" />
			</material>
		</visual>

		<collision>
			<origin xyz="0 0 0" rpy="0 0 0" />
			<geometry>
				<box size="0.01 0.01 0.01" />
			</geometry>
		</collision>
	</link>

	<joint name="base_swivel_joint" type="continuous">
		<origin xyz="-0.185 0 0.055" rpy="0 0 0" />
		<axis xyz="0 0 1" />
		<anchor xyz="0 0 0" />
		<limit effort="100" velocity="100" k_velocity="0" />
		<joint_properties damping="0.0" friction="0.0" />
		<parent link="base_link" />
		<child link="swivel" />
	</joint>
  <gazebo reference="swivel">
    <material>Gazebo/Grey</material>
  </gazebo>

<!-- center_hubcap -->
	<link name="center_hubcap">
		<inertial>
			<mass value="0.01" />
			<origin xyz="0 0 0" />
			<inertia ixx="0.012411765597" ixy="-0.000711733678" ixz="0.00050272983"
				iyy="0.015218160428" iyz="-0.000004273467" izz="0.011763977943" />
		</inertial>

		<visual name="base_visual">
			<origin xyz="0 0 0" rpy="0 0 0" />
			<geometry name="pioneer_geom">
				<mesh filename="package://p3dx_description/meshes/center_hubcap.stl" />
			</geometry>
			<material name="swivel">
				<color rgba="0.5 0.5 0.5 1" />
			</material>
		</visual>

		<collision>
			<origin xyz="0 0 0" rpy="0 0 0" />
			<geometry>
				<box size="0.01 0.01 0.01" />
			</geometry>
		</collision>
	</link>

	<joint name="swivel_hubcap_joint" type="continuous">
		<origin xyz="-0.026 0 -0.016" rpy="0 0 0" />
		<axis xyz="0 1 0" />
		<anchor xyz="0 0 0" />
		<limit effort="100" velocity="100" k_velocity="0" />
		<joint_properties damping="0.0" friction="0.0" />
		<parent link="swivel" />
		<child link="center_wheel" />
	</joint>
	<gazebo reference="center_hubcap">
		<material>Gazebo/Grey</material>
	</gazebo>
  
<!-- center_wheel -->
	<link name="center_wheel">
		<inertial>
			<mass value="0.1" />
			<origin xyz="0 0 0" />
			<inertia ixx="0.012411765597" ixy="-0.000711733678" ixz="0.00050272983"
				iyy="0.015218160428" iyz="-0.000004273467" izz="0.011763977943" />
		</inertial>

		<visual name="base_visual">
			<origin xyz="0 0 0" rpy="0 0 0" />
			<geometry name="pioneer_geom">
				<mesh filename="package://p3dx_description/meshes/center_wheel.stl" />
			</geometry>
			<material name="WheelBlack">
				<color rgba="0.117 0.117 0.117 1" />
			</material>
		</visual>

		<collision>
			<origin xyz="0 0 0" rpy="-1.57 0 0" />
			<geometry>
				<cylinder radius="0.0375" length="0.01" />
			</geometry>
		</collision>
	</link>

	<joint name="center_wheel_joint" type="fixed">
		<origin xyz="-0.0035 0 -0.001" rpy="0 0 0"/>
		<parent link="center_wheel"/>
		<child link="center_hubcap"/>
	</joint>
	<gazebo reference="center_wheel">
		<material>Gazebo/Black</material>
		<mu1>10.0</mu1>
		<mu2>10.0</mu2>
		<kp>1000000.0</kp>
		<kd>1.0</kd>
	</gazebo>

<!-- front_sonar -->
	<link name="front_sonar">
		<inertial>
			<mass value="0.0001" />
			<origin xyz="0 0 0" />
			<inertia ixx="1" ixy="0" ixz="0" iyy="1" iyz="0" izz="1" />
		</inertial>
		
		<visual name="front_sonar_vis">
			<origin rpy="0 0 0" xyz="0 0 0" />
			<geometry name="pioneer_geom">
				<mesh filename="package://p3dx_description/meshes/front_sonar.stl" />
			</geometry>
			<material name="SonarYellow">
				<color rgba="0.715 0.583 0.210 1.0" />
			</material>
		</visual>
		
		<collision>
			<origin rpy="0 0 0" xyz="0 0 0" />
			<geometry>
				<box size="0.01 0.01 0.01" />
			</geometry>
		</collision>
	</link>
	
	<joint name="base_front_joint" type="fixed">
		<origin rpy="0 0 0" xyz="0.109 0 0.209" />
		<parent link="base_link" />
		<child link="front_sonar" />
	</joint>
  <gazebo reference="front_sonar">
    <material value="Gazebo/Yellow" />
  </gazebo>

  	

<!-- lms100 laser -->
	<link name="lms100">
		<inertial>
			<mass value="1e-5" />
			<origin xyz="0 0 0" rpy="0 0 0" />
			<inertia ixx="1e-6" ixy="0" ixz="0" iyy="1e-6" iyz="0" izz="1e-6" />
		</inertial>

		<visual>
			<origin xyz="0 0 0" rpy="0 0 0" />
			<geometry>
				<mesh filename="package://p3dx_description/meshes/lms100.dae" />     
			</geometry>
		</visual>

		<collision>
			<origin xyz="0 0 0" rpy="0 0 0" />
			<geometry>
				<box size="0.01 0.01 0.01" />
			</geometry>
		</collision>
	</link>

	<joint name="lms100_joint" type="fixed">
		<axis xyz="0 1 0" />
		<origin xyz="0.16 0 0.15" rpy="0 0 0" />
		<parent link="base_link" />
		<child link="lms100" />
	</joint>
	<gazebo reference="lms100">
		<sensor type="ray" name="head_hokuyo_sensor">
			<pose>0 0 0 0 0 0</pose>
			<visualize>false</visualize>
			<update_rate>50</update_rate>
			<ray>
				<scan>
					<horizontal>
						<samples>360</samples>
						<resolution>1</resolution>
						<min_angle>-1.570796</min_angle>
						<max_angle>1.570796</max_angle>
					</horizontal>
				</scan>
				<range>
					<min>0.10</min>
					<max>30.0</max>
					<resolution>0.01</resolution>
				</range>
				<noise>
					<type>gaussian</type>
					<!-- Noise parameters based on published spec for Hokuyo laser achieving 
						"+-30mm" accuracy at range < 10m. A mean of 0.0m and stddev of 0.01m will 
						put 99.7% of samples within 0.03m of the true reading. -->
					<mean>0.0</mean>
					<stddev>0.01</stddev>
				</noise>
			</ray>
			<plugin name="gazebo_ros_head_hokuyo_controller" filename="libgazebo_ros_laser.so">
				<topicName>${ns}/laser/scan</topicName>
				<frameName>lms100</frameName>
			</plugin>
		</sensor>
	</gazebo>
  
<!-- wheel -->
		<link name="p3dx_right_wheel">
			<inertial>
				<mass value="0.5" />
				<origin xyz="0 0 0" />
				<inertia ixx="0.012411765597" ixy="0" ixz="0" iyy="0.015218160428"
					iyz="0" izz="0.011763977943" />
			</inertial>

			<visual name="base_visual">
				<origin xyz="0 0 0" rpy="0 0 0" />
				<geometry name="pioneer_geom">
					<mesh filename="package://p3dx_description/meshes/right_wheel.stl" />
				</geometry>
				<material name="WheelBlack">
					<color rgba="0.117 0.117 0.117 1" />
				</material>
			</visual>

			<collision>
				<origin xyz="0 0 0" rpy="-1.57 0 0" />
				<geometry>
					<cylinder radius="0.09" length="0.01" />
				</geometry>
			</collision>
		</link>

		<joint name="base_right_wheel_joint" type="continuous">
			<axis xyz="0 1 0" />
			<anchor xyz="0 0 0" />
			<limit effort="100" velocity="100" />
			<joint_properties damping="0.0" friction="0.0" />
			<origin xyz="0 -0.158 0.091" rpy="0 0 0" />
			<parent link="base_link" />
			<child link="p3dx_right_wheel" />
		</joint>
		
		<!-- hubcap -->
		<link name="p3dx_right_hubcap">
			<inertial>
				<mass value="0.01" />
				<origin xyz="0 0 0" />
				<inertia ixx="0.012411765597" ixy="0" ixz="0" iyy="0.015218160428"
					iyz="0" izz="0.011763977943" />
			</inertial>

			<visual name="base_visual">
				<origin xyz="0 0 0" rpy="0 0 0" />
				<geometry name="pioneer_geom">
					<mesh filename="package://p3dx_description/meshes/right_hubcap.stl" />
				</geometry>

				<material name="HubcapYellow">
					<color rgba="1.0 0.811 0.151 1.0" />
				</material>
			</visual>

			<collision>
				<origin xyz="0 0 0" rpy="0 0 0" />
				<geometry>
					<box size="0 0 0" />
				</geometry>
			</collision>
		</link>
		<joint name="base_right_hubcap_joint" type="fixed">
			<origin xyz="0 0 0" rpy="0 0 0" />
			<parent link="p3dx_right_wheel" />
			<child link="p3dx_right_hubcap" />
		</joint>

	    <transmission name="base_link_right_wheel_trans">
	      <type>pr2_mechanism_model/SimpleTransmission</type>
	      <joint name="base_right_wheel_joint" />
	      <actuator name="base_right_wheel_motor">
		<hardwareInterface>EffortJointInterface</hardwareInterface>
		<mechanicalReduction>${-1 * 624/35 * 80/19}</mechanicalReduction>
	      </actuator>
	    </transmission>

			<gazebo reference="p3dx_right_hubcap">
				<material>Gazebo/Yellow</material>
			</gazebo>

			<gazebo reference="p3dx_right_wheel">
				<material>Gazebo/Black</material>
				<mu1>0.5</mu1>
				<mu2>50.0</mu2>
				<kp>100000000.0</kp>
				<kd>1.0</kd>
			</gazebo>



	<!-- left hubcap + wheel -->
	<!-- <xacro:macro name="p3dx_wheel" params="suffix parent reflect">-->
	
		<!-- wheel -->
		<link name="p3dx_left_wheel">
			<inertial>
				<mass value="0.5" />
				<origin xyz="0 0 0" />
				<inertia ixx="0.012411765597" ixy="0" ixz="0" iyy="0.015218160428"
					iyz="0" izz="0.011763977943" />
			</inertial>

			<visual name="base_visual">
				<origin xyz="0 0 0" rpy="0 0 0" />
				<geometry name="pioneer_geom">
					<mesh filename="package://p3dx_description/meshes/left_wheel.stl" />
				</geometry>
				<material name="WheelBlack">
					<color rgba="0.117 0.117 0.117 1" />
				</material>
			</visual>

			<collision>
				<origin xyz="0 0 0" rpy="-1.57 0 0" />
				<geometry>
					<cylinder radius="0.09" length="0.01" />
				</geometry>
			</collision>
		</link>

		<joint name="base_left_wheel_joint" type="continuous">
			<axis xyz="0 1 0" />
			<anchor xyz="0 0 0" />
			<limit effort="100" velocity="100" />
			<joint_properties damping="0.0" friction="0.0" />
			<origin xyz="0 0.158 0.091" rpy="0 0 0" />
			<parent link="base_link" />
			<child link="p3dx_left_wheel" />
		</joint>
		
		<!-- hubcap -->
		<link name="p3dx_left_hubcap">
			<inertial>
				<mass value="0.01" />
				<origin xyz="0 0 0" />
				<inertia ixx="0.012411765597" ixy="0" ixz="0" iyy="0.015218160428"
					iyz="0" izz="0.011763977943" />
			</inertial>

			<visual name="base_visual">
				<origin xyz="0 0 0" rpy="0 0 0" />
				<geometry name="pioneer_geom">
					<mesh filename="package://p3dx_description/meshes/left_hubcap.stl" />
				</geometry>

				<material name="HubcapYellow">
					<color rgba="1.0 0.811 0.151 1.0" />
				</material>
			</visual>

			<collision>
				<origin xyz="0 0 0" rpy="0 0 0" />
				<geometry>
					<box size="0 0 0" />
				</geometry>
			</collision>
		</link>
		<joint name="base_left_hubcap_joint" type="fixed">
			<origin xyz="0 0 0" rpy="0 0 0" />
			<parent link="p3dx_left_wheel" />
			<child link="p3dx_left_hubcap" />
		</joint>

	    <transmission name="base_link_left_wheel_trans">
	      <type>pr2_mechanism_model/SimpleTransmission</type>
	      <joint name="base_left_wheel_joint" />
	      <actuator name="base_left_wheel_motor">
		<hardwareInterface>EffortJointInterface</hardwareInterface>
		<mechanicalReduction>${1 * 624/35 * 80/19}</mechanicalReduction>
	      </actuator>
	    </transmission>

			<gazebo reference="p3dx_left_hubcap">
				<material>Gazebo/Yellow</material>
			</gazebo>

			<gazebo reference="p3dx_left_wheel">
				<material>Gazebo/Black</material>
				<mu1>0.5</mu1>
				<mu2>50.0</mu2>
				<kp>100000000.0</kp>
				<kd>1.0</kd>
			</gazebo>
	
  
	

  <!-- ros_control plugin -->
  <gazebo>
    <plugin name="gazebo_ros_control" filename="libgazebo_ros_control.so">
      <robotNamespace>/${ns}</robotNamespace>
    </plugin>
  </gazebo>

<!-- differential drive -->
	<gazebo>
        <plugin name="differential_drive_controller" filename="libgazebo_ros_diff_drive.so">
            <rosDebugLevel>Debug</rosDebugLevel>
            <robotNamespace></robotNamespace>
            <publishWheelTF>false</publishWheelTF>
            <publishWheelJointState>true</publishWheelJointState>
            <alwaysOn>true</alwaysOn>
            <leftJoint>left_hub_joint</leftJoint>
            <rightJoint>right_hub_joint</rightJoint>
            <wheelSeparation>0.3</wheelSeparation>
            <wheelDiameter>0.18</wheelDiameter>
            <wheelTorque>20</wheelTorque>
            <wheelAcceleration>1.8</wheelAcceleration>
            <commandTopic>cmd_vel</commandTopic>
            <odometryTopic>odom</odometryTopic>
            <odometryFrame>odom</odometryFrame>
            <odometrySource>world</odometrySource>
            <robotBaseFrame>base_link</robotBaseFrame>
            <updateRate>10.0</updateRate>
        </plugin>

	</gazebo>

  <!-- ground truth -->
	<gazebo>
		<plugin name="p3d_base_controller" filename="libgazebo_ros_p3d.so">
			<alwaysOn>true</alwaysOn>
			<updateRate>100.0</updateRate>
			<bodyName>base_link</bodyName>
			<topicName>${ns}/base_pose_ground_truth</topicName>
			<gaussianNoise>0.01</gaussianNoise>
			<frameName>map</frameName>
			<!-- initialize odometry for fake localization -->
			<xyzOffsets>0 0 0</xyzOffsets>
			<rpyOffsets>0 0 0</rpyOffsets>
		</plugin>
	</gazebo>


</robot>
